Workbook

Sheet README
B2: Status | C2: Definition
B3: In Design | C3: Test case is being written or updated. Requirements are being analyzed Steps and expected results are being documented Not ready for execution
B4: Ready | C4: Test case is fully designed and approved for execution. Steps complete Test data identified Awaiting execution
B5: Review Completed | C5: Test case has been peer-reviewed or approved by QA Lead / Business. Content validated Coverage confirmed No design gaps Ready for formal execution
B6: Pass | C6: Test case executed successfully. Actual result matches expected result No defect logged Functionality works as designed
B7: Fail | C7: Test case executed and did not meet expected result. Defect identified Defect logged in tracking system Requires fix and retest
B8: Blocked | C8: Test case cannot be executed due to external dependency. Examples: Environment issue Data unavailable Integration down Build not deployed Access issue
B9: No Run | C9: Test case has not yet been executed. Not started Waiting for environment Waiting for release window Still in backlog

Sheet Coaching log
A1: if Yellow | B1: Existing Defects
A2: =COUNT(A4:A61) -> 58
A3: Test Case ID | B3: Test Description/Title | C3: Module / Feature | D3: Preconditions | E3: Test Steps | F3: Test Data/ User | G3: Expected Result | H3: Actual outcome | I3: Status | J3: Existing Defect
A4: 1 | B4: Verify that admin has login to ECMS SF application | C4: Monitoring log /Coaching log | E4: Login SF-->ECMS Application | F4: Internal admin | G4: The vendor is able to login to ECMS SF homepage | H4: working as Excepted | I4: Pass
A5: 2 | B5: The admin is able to create a coaching log | C5: Monitoring log /Coaching log | D5: That admin should be Provisioned perfectly with the Required Permission sets | E5: Home page-->Coaching log tab | F5: Internal admin | G5: The admin is able to create a new coaching log which is populated by selecting role based log form | H5: working as Excepted | I5: Pass | J5: https://prutech.atlassian.net/browse/DOEECMS-1910 https://prutech.atlassian.net/browse/DOEECMS-2020
A6: 3 | E6: Coaching log--> new
A7: 4 | E7: Fill the required feilds Based on populated Role based log
A8: 5 | E8: Coaching log--> Instructional log
A9: 6 | E9: Coaching Log -->save --> Draft | G9: The admin is able to create a new coaching log which is populated by selecting role based log form
A10: 7 | B10: Verify that Admin is able to create a Goal in the Log | C10: Monitoring log /Coaching log | D10: Permissions Set Group -- Internal admin ECMS Instructional Coordinators ECMS Leadership Coaches ECMS Social Workers | E10: Coaching log-->Recently viewed | F10: Internal admin | G10: Internal administrators can conduct individual sessions, set goals, provide feedback, and collaborate on strategies for professional growth, using the coaching log to track the conversations and progress. ​ | H10: working as Excepted | I10: Pass
A11: 8 | E11: Coaching log-->select desired log link
A12: 9 | E12: Coaching log -->open-->Quick links
A13: 10 | E13: Coaching log-->Quick links-->Goals
A14: 11 | E14: Coaching log -->Goals--> new Goal
A15: 12 | E15: coaching log --> save
A16: 13 | B16: Verify that Internal administrators can edit coaching goals. | C16: Monitoring log /Coaching log | E16: Coaching log-->Recently Viewed log | F16: Internal admin | G16: The admin is able to edit goals from the log | H16: working as Excepted | I16: Pass | J16: https://prutech.atlassian.net/browse/DOEECMS-1905 https://prutech.atlassian.net/browse/DOEECMS-2038
A17: 14 | E17: Coaching log-->select desired log link
A18: 15 | E18: Coaching log -->open-->Quick links
A19: 16 | E19: Coaching log-->Quick links-->Goals
A20: 17 | E20: Coaching log -->Goals--> Edit
A21: 18 | E21: coaching log --> save
A22: 19 | B22: verify that Site Based Coaching Log Goals can be viewed by the internal administrator. | C22: Monitoring log /Coaching log | E22: Home page -> Site master | F22: Internal admin | G22: The admin is able to view Site Based Coaching Log Goals can be viewed by the internal administrator. | H22: working as Excepted | I22: Pass
A23: 20 | E23: Site master --> Required link -->open Site ID
A24: 21 | B24: Internal administrators can edit coaching log entries for instructional coaches and social workers to record their coaching experiences, strategies employed, and insights gained. From the edit screen, users can access the fidelity tool. ​ | C24: Monitoring log /Coaching log | E24: Home page-->Coaching log tab | F24: Internal admin | G24: The admin is able to select and edit the logs based their coaching experiences, strategies employed, and insights gained. From the edit screen, users can access the fidelity tool. ​ | H24: working as Excepted | I24: Pass | J24: https://prutech.atlassian.net/browse/DOEECMS-1906
A25: 22 | E25: Coaching log--> Recently Viewed
A26: 23 | E26: Coaching log--> Instructional log
A27: 24 | E27: Coaching Log --> Draft Status
A28: 25 | E28: Coaching log -->Edit button
A29: 26 | E29: coaching log -->Fidelity Tool -->based on experiences
A30: 27 | B30: Internal administrators can email coaching log entries to other ECMS users to review.​ | C30: Monitoring log /Coaching log | E30: Tab--> Coaching log | F30: Internal admin | G30: View the email draft screen that popped-up in the lower righthand corner. ​Enter your desired fields and begin composing your email. ​Add in Desired Fields from the Coaching Log Entry.​ ​ | H30: Not working as Excepted | I30: Fail | J30: https://prutech.atlassian.net/browse/DOEECMS-2037
A31: 28 | E31: coaching log --> open log hyper link
A32: 29 | E32: coaching log-->Activitytab
A33: 30 | E33: coaching log -->Click on Email
A34: 31 | E34: coaching log --> left corner compose mail
A35: 32 | E35: coaching log--> Merge fields
A36: 33 | E36: coaching log --> Send
A37: 34 | B37: Verify that Internal administrators may view previously created coaching logs and its details by sites. | C37: Monitoring log /Coaching log | E37: Homepage--> Site master site master-->site ID site ID -->Quick links-->view all -->coaching logs | F37: Internal admin | G37: Internal administrators are able to view previously created coaching logs and its details by sites. | H37: working as Excepted | I37: Pass
A38: 35 | E38: site master-->site ID
A39: 36 | E39: site ID -->Quick links-->view all -->coaching logs
A40: 37 | B40: Verify that Internal administrators may view and update Site Visit Frequency | C40: Monitoring log /Coaching log | E40: Home Page --> Site Master | F40: Internal admin | G40: The internal admin is able to View and visit the site Frequncy able to Update the Visit Frequncy | H40: working as Excepted | I40: Pass
...

Sheet Attendance
A1: =COUNT(A3:A97) -> 95 | B1: Total Test Cases
A2: Test Case ID | B2: Test Description/Title | C2: Module / Feature | D2: Functionality | E2: Test Type | F2: Preconditions | G2: Test Steps | H2: Test Data/ User | I2: Expected Result | J2: Actual Result | K2: Status | L2: Defect Retest reference
A3: 1 | B3: Vendor Admin should be able to create weekly attendance to the enrolled student | C3: Attendance | D3: Attendance/Weekly | E3: Positive | F3: Student should be enrolled under site and Approved by Enrollment Specialist. Enrollment should be in Approved status | G3: Login to ECMS portal as a Vendor | H3: Ravi Krishna | I3: Vendor Admin should be able to create weekly attendance to the enrolled student | J3: Working as Expected | K3: Pass
A4: 1 | C4: Attendance | D4: Attendance/Weekly | E4: Positive | G4: Click on Attendance → Weekly Attendance → Select EBC Site → Select JuniorKG Class | I4: User is able to select Junior KG Class | J4: Working as Expected | K4: In Design
A5: 1 | C5: Attendance | D5: Attendance/Weekly | E5: Positive | G5: Select Student name → Select Week | K5: In Design
A6: 1 | C6: Attendance | D6: Attendance/Weekly | E6: Positive | G6: Enter Status as Present --> Add 1st Check In and Check Out timings --> Save | K6: In Design
A7: 1 | B7: Vendor Admin should be able to create weekly attendance for 2nd Check In and Check Out | C7: Attendance | D7: Attendance/Weekly/2nd Check in and Check Out | E7: Positive | F7: Student should be enrolled under site and Approved by Enrollment Specialist. Enrollment should be in Approved status | G7: Login to ECMS portal as a Vendor | H7: Ravi Krishna | I7: 2nd Check In and Check Out timings should be saved | J7: Receiving successful message but record is not getting saved. | K7: Fail | L7: DOEECMS-1885
A8: 1 | C8: Attendance | D8: Attendance/Weekly/2nd Check in and Check Out | E8: Positive | G8: Click on Attendance → Weekly Attendance → Select EBC Site → Select JuniorKG Class | K8: In Design
A9: 1 | C9: Attendance | D9: Attendance/Weekly/2nd Check in and Check Out | E9: Positive | G9: Select Student name → Enter 2nd Check In and Check Out timings → Save | K9: In Design
A10: 1 | B10: Vendor Admin should be able to create Daily Attendance to the enrolled student | C10: Attendance | D10: Attendance/Daily | E10: Positive | F10: Student should be enrolled under site and Approved by Enrollment Specialist. Enrollment should be in Approved status | G10: Login to ECMS portal as a Vendor | H10: Ravi Krishna | I10: Only one entry should present for one day. | J10: Duplicate records getting created | K10: Fail | L10: DOEECMS-1889
A11: 1 | C11: Attendance | D11: Attendance/Daily | E11: Positive | G11: Click on Attendance → Daily Attendance → Select EBC Site → Select JuniorKG Class | K11: Pass
A12: 1 | C12: Attendance | D12: Attendance/Daily | E12: Positive | G12: Select Student name → Select date (eg Jan 15, 2026) | K12: Pass
A13: 1 | C13: Attendance | D13: Attendance/Daily | E13: Positive | G13: Enter Status as Present --> Add Check In and Check Out timings --> Save | K13: Pass
A14: 1 | B14: Vendor Admin should be able to submit Monthly Review | C14: Attendance | D14: Attendance/Monthly Review | E14: Positive | F14: Vendor should fill roaster for the particular month | G14: Login to ECMS portal as a Vendor | H14: Ravi Krishna | I14: Able to submit | J14: Working as Expected | K14: Pass
A15: 1 | C15: Attendance | D15: Attendance/Monthly Review | E15: Positive | G15: Click on Attendance → Daily Attendance → Select EBC Site → Select JuniorKG Class | K15: Pass
A16: 1 | C16: Attendance | D16: Attendance/Monthly Review | E16: Positive | G16: Select Attendance Month --> Attendance Class | K16: Pass
A17: 1 | C17: Attendance | D17: Attendance/Monthly Review | E17: Positive | G17: click checkbox --> submit | K17: Pass
A18: 1 | B18: Daily Attendance should not allow before Admission Date | C18: Attendance | D18: Attendance/Dates | E18: Negative | F18: Student should be enrolled under site and Approved by Enrollment Specialist. Enrollment should be in Approved status | G18: Login to ECMS portal as a Vendor | H18: Ravi Krishna | I18: System should not allow before Admission date (1/1/2026) | J18: The system allowed users to enter attendance before the student’s Admission Date(First Day of Attendance) | K18: Fail | L18: DOEECMS-1896
A19: 1 | G19: Click on Attendance → Daily Attendance → Select EBC Site → Select JuniorKG Class | K19: Pass
A20: 1 | G20: Select Student name → Select date (eg Dec 02, 2025) | K20: Pass
A21: 1 | G21: Fill Check In and Check Out timings and Save | K21: Pass
A22: 1 | B22: Internal Admin should have access to view Attendance Dashboards | C22: Attendance | D22: Attendance/Dashboards | E22: Positive | F22: Vendor Admit should submit Monthly review report | G22: Login to SF ECMS Application as Internal Admin | H22: Ravi Krishna | I22: Internal Admin should have access to view Attendance Dashboards | K22: Fail | L22: DOEECMS-1897
A23: 1 | C23: Attendance | D23: Attendance/Dashboards | E23: Positive | G23: Check Dashboards on Home Page | K23: Pass
A24: 1 | B24: Verify that admin is able to take attendance for enrollment is in submitted, approved and active in Status | C24: Attendance | D24: Attendance/Enrollment/Status | E24: Positive | F24: Enrollment should be in Submitted or Approved Or Active | G24: Log-->Portal | H24: Bunny | J24: Working as Expected | K24: Pass
A25: 1 | G25: Portal-->Attendance tab-->select Submitted Enrollment student
A26: 1 | G26: Portal--> Take Attendance | I26: Vendor Admin is able to take attendance for the enrollement submitted student
A27: 1 | B27: Attendance Date Should Not Be Before Student DOB | C27: Attendance | D27: Attendance/Dates | E27: Positive | G27: Login to Vendor Portal | I27: System should restrict attendance entry for dates before the Student DOB and display a validation error message. | J27: Attendance is saved successfully | K27: Pass | L27: https://prutech.atlassian.net/browse/DOEECMS-1982
A28: 1 | G28: Click on Attendance Tab --> Select weekly Attendance
A29: 1 | G29: Select Site --> class --> Select a student whose DOB is after First day of attendance
A30: 1 | G30: Fill attendance with check in/out days
A31: 1 | G31: Save the attendance | I31: Attendance is saved successfully
A32: 1 | B32: Verify record should not get saved if no status is given | C32: Attendance | D32: Attendance/Enrollment/Status | E32: Negative | G32: login portal → attendance tab | K32: Pass | L32: https://prutech.atlassian.net/browse/DOEECMS-1988
A33: 1 | G33: select student and try to take attendance without giving and with giving status as present don’t select the checkin and checkout time and click save | I33: It has to be restrict without filling the data it should not get save | J33: It was showing that record has sucessfully saved message | K33: Pass
A34: 1 | B34: Verify 2nd Check In/out fields Should be displayed in Backend in Attendance Information | C34: Attendance | D34: Attendance/Weekly/2nd Check in and Check Out | E34: Positive | G34: Login to Vendor Portal | I34: 2nd Check In/out fields should be displayed in Backend in Attendance Information, so that admin can check the data provided by vendor and make changes if required. | J34: 2nd Check In/out fields are not displayed in Backend in Attendance Information | K34: Pass | L34: https://prutech.atlassian.net/browse/DOEECMS-1983
A35: 1 | G35: Click on Attendance Tab --> Select weekly Attendance
A36: 1 | G36: Select Site --> class --> student --> Fill attendance with 2nd Check In/out fields
A37: 1 | G37: Save the attendance
A38: 1 | G38: Log into Backend as System Admin and check the student Contact --> Attendance Info
A39: 1 | G39: 2nd Check In/out fields are missing | I39: 2nd Check In/out fields should be displayed in Backend in Attendance Information, so that admin can check the data provided by vendor and make changes if required.
A40: 1 | B40: When accessing the Attendance module as a CBO Staff user on the portal, navigating to the Weekly Attendance feature results in an error message. | C40: Attendance | D40: Error Displayed When Accessing Weekly Attendance for CBO Staff User | G40: 1. Navigate to the Attendance module | I40: The Weekly Attendance page should load successfully without any errors. | J40: An error message is displayed on the Weekly Attendance page asking the user to refresh. Refreshing the page does not resolve the issue, and the error persists. | K40: Pass | L40: https://prutech.atlassian.net/browse/DOEECMS-1780
...

Sheet Budget
A2: Test Case ID | B2: Module / Feature | C2: Functionality | D2: Test Type | E2: Test Scenario | F2: Preconditions | G2: Test Steps | H2: Test Data | I2: Expected Result | J2: Status | K2: Priority | L2: Defect Retest reference
A3: 1 | B3: Budget | C3: Budget/NewBudget | D3: Positive | E3: Vendor Admin (Experience User) Should be able create a new Budget from Site > ECMS Contract | F3: User is an Experience Cloud user (active) tied to a Contact under the Vendor Account. User is assigned to ECMS Vendor Admin External Permission Assignment Group (as you confirmed). Vendor Account has: At least one active Site visible to the vendor user in portal At least one ECMS Contract linked/available for that Site (and in valid FY/status to allow budgeting) User can successfully log into the ECMS Portal. | G3: Log in to ECMS Portal as Experience user (Vendor Admin). | I3: Confirm user is successfully logged in | J3: Reviewed Completed | L3: DOEECMS-1867
A4: 2 | B4: Budget | C4: Budget/NewBudget | D4: Positive | G4: From the portal menu, open Site. | I4: Confirm site is launched successfully | J4: Reviewed Completed
A5: 3 | B5: Budget | C5: Budget/NewBudget | D5: Positive | G5: Select a valid Site record. | I5: confirm system accept user input | J5: Reviewed Completed
A6: 4 | B6: Budget | C6: Budget/NewBudget | D6: Positive | G6: Click ECMS Contract (related section / tab / related list). | I6: Verify system should show all related contracts | J6: Reviewed Completed
A7: 5 | B7: Budget | C7: Budget/NewBudget | D7: Positive | G7: Open the relevant ECMS Contract record. | I7: Verify ECMS contract record is open | J7: Reviewed Completed
A8: 6 | B8: Budget | C8: Budget/NewBudget | D8: Positive | G8: Click Create New Budget. | I8: System should open the New Budget page / Budget creation flow and allow the user to: Select FY / Site / Contract Type (as applicable) Save Budget as Draft See Budget record created and visible under Budgets list Expected Outcome: Budget creation screen loads and a new Budget record can be created. | J8: Reviewed Completed
A9: 7 | B9: Budget | C9: Budget/NewBudget | D9: Positive | E9: Site Manager (Experience User) Should be able create a new Budget from Site > ECMS Contract | F9: User is an Experience Cloud user (active) tied to a Contact under the Vendor Account. User is assigned to ECMS Site Manager External Permission Assignment Group (as you confirmed). Vendor Account has: At least one active Site visible to the vendor user in portal At least one ECMS Contract linked/available for that Site (and in valid FY/status to allow budgeting) User can successfully log into the ECMS Portal. | G9: Log in to ECMS Portal as Experience user (Site Manager). | I9: Successfully logged in | J9: Reviewed Completed
A10: 8 | B10: Budget | C10: Budget/NewBudget | D10: Positive | G10: From the portal menu, open Site. | I10: Confirm user land on the site | J10: Reviewed Completed
A11: 9 | B11: Budget | C11: Budget/NewBudget | D11: Positive | G11: Select a valid Site record. | I11: Confirm valid site record is selected | J11: Reviewed Completed
A12: 10 | B12: Budget | C12: Budget/NewBudget | D12: Positive | G12: Click ECMS Contract (related section / tab / related list). | I12: Confirm user land on related list tab | J12: Reviewed Completed
A13: 11 | B13: Budget | C13: Budget/NewBudget | D13: Positive | G13: Open the relevant ECMS Contract record. | I13: Confirm relevant contract record is selected | J13: Reviewed Completed
A14: 12 | B14: Budget | C14: Budget/NewBudget | D14: Positive | G14: Click Create New Budget. | I14: confirm user land on budget page | J14: Reviewed Completed
A15: 13 | B15: Budget | C15: Budget/NewBudget | D15: Positive | E15: When a vendor submits a budget for approval or the budget is approved by OA and sent to OD for next level approval, the Items to Approve component on the ECMS Home Page should display a single entry | G15: Submit the budget using Submit Budget (for vendor portal) or Approve Budget as OA AND Sent for approval to OD. | I15: Confirm budget is sent to approval | J15: Reviewed Completed | L15: DOEECMS-1804
A16: 14 | B16: Budget | C16: Budget/NewBudget | D16: Positive | G16: Log in as an Internal DECE user (OA/OD). | I16: Confirm user is succesfully logged in | J16: Reviewed Completed
A17: 15 | B17: Budget | C17: Budget/NewBudget | D17: Positive | G17: Navigate to the Home Page. | I17: Confirm user lands on home page | J17: Reviewed Completed
A18: 16 | D18: Positive | G18: Review the Items to Approve component. | I18: Only one approval entry should appear for each budget submitted. The component should display a single actionable record corresponding to the submitted budget. | J18: Reviewed Completed
A19: 17 | B19: Budget | C19: Amend Budget with Contact Change | D19: Positive | E19: Verify user should be able to change POC Contact when Amending a Budget | F19: Vendor user has valid Community Portal access and required permissions to amend budgets. An existing Budget is in status Approved by DOE. An Invoice exists for the same Site/Contract/Budget context and is currently in Saved status (not submitted). Budget is visible to the Vendor user in the Community Portal. | G19: Login to ECMS Community Portal as Vendor Management / Vendor Admin user. | I19: Accept the New Contact selection, Persist the selected Contact for the amendment context, and Allow the user to proceed to the next step of the amendment flow (continue amendment of the budget). | J19: Reviewed Completed
A20: 18 | D20: Positive | G20: Navigate to Budgets. | I20: lands on budget list | J20: Reviewed Completed
A21: 19 | D21: Positive | G21: Open an existing Budget that is Approved and has an Invoice created in Saved status. | I21: and has an Invoice created in Saved status. | J21: Reviewed Completed
A22: 20 | D22: Positive | G22: Click Amend Budget. | I22: Budget is now open in amend and new Budget ID is generated | J22: Reviewed Completed
A23: 21 | D23: Positive | G23: In the amendment flow, navigate to the Budget Information screen. | I23: confirm budget information screen should display | J23: Reviewed Completed
A24: 22 | D24: Positive | G24: Select the radio button New Contact. | I24: Confirm system allow user action | J24: Reviewed Completed
A25: 23 | D25: Positive | G25: Choose a new Contact from the list (lookup/picklist). | I25: Confirm system allow user to select new contact from the list | J25: Reviewed Completed
A26: 24 | D26: Positive | G26: Click Next. | I26: confirm user should be able to change the contact | J26: Reviewed Completed
A27: 25 | D27: Positive | E27: Verify Budget deletion by System Admin | F27: System Admin should be logged into the system | G27: Navigate to required budget in SF and click on "delete" from the action dropdown. | I27: Delete budget prompt gets displayed | J27: Reviewed Completed
G28: Click on "Delete" on the Delete Budget prompt | I28: Budget gets deleted and is no longer available in the system | J28: Reviewed Completed
E29: Verify non-system admin can't delete a budget | F29: Non- System Admin should be logged into the system | G29: Navigate to required budget in SF and click on the action dropdown in the right. | I29: Delete option should not be displayed in the dropdown | J29: Reviewed Completed
A30: 26 | B30: Budget | C30: Update Line Items | D30: Positive | E30: Verify Vendor admin should be able to update line items | F30: Budget should be saved and available | G30: Log in as a Vendor user with ECMS Budgets – External permission set. | I30: confirm user is successfully logged in | J30: Reviewed Completed | L30: DOEECMS-1802
A31: 27 | B31: Budget | C31: Update Line Items | D31: Positive | G31: Navigate to Budgets. | I31: Confirm budget page displays | J31: Reviewed Completed
A32: 28 | B32: Budget | C32: Update Line Items | D32: Positive | G32: Open any Saved Budget record. | I32: confirm user should be able to open budget | J32: Reviewed Completed
A33: 29 | B33: Budget | C33: Update Line Items | D33: Positive | G33: Click the dropdown in the top‑right and select Update Line Items. | I33: confirm user should be able to update line items | J33: Reviewed Completed
A34: 30 | B34: Budget | C34: Update Line Items | D34: Positive | G34: Observe system behavior. | I34: Vendor should be able to add/edit line items | J34: Reviewed Completed
A35: 31 | B35: Budget | C35: Create/Edit | E35: Verify External User shoud be able to Create Budget | F35: User is an Experience Cloud user (active) tied to a Contact under the Vendor Account. User is assigned required Permission Assignment Group . Vendor Account has: At least one active Site visible to the vendor user in portal At least one ECMS Contract linked/available for that Site (and in valid FY/status to allow budgeting) User can successfully log into the ECMS Portal. | G35: 1)Navigate to Budgets and click Create New Budget | I35: Budget page will open | J35: Reviewed Completed
G36: 2)Enter required budget details | I36: Budget details will get entered | J36: Reviewed Completed
G37: 3)Click Save | I37: A confirmation message should be displayed and the budget status should be set to the expected initial status (e.g., Draft/Saved) The budget record should display the selected Contact and Total Amount | J37: Reviewed Completed
E38: Amend an existing budget-Update/contact an amount | F38: User is logged in into the system and a submitted budget is available for amendment. | G38: View the budget details page and click on Amend Budget | I38: Amend budget screen will open | J38: Ready
G39: Select/change the contact as desired | I39: Contact gets selected. | J39: Ready
A40: 32 | G40: Update other data(line items, classes and documents) as required and click on next | I40: Amended budget should get saved | J40: Ready
G41: Check Amended Level. “A” indicates one amendment; “B” indicates two amendments; “C” indicates three amendments. Click the links to any related budget to view the detailed record for that prior version. | I41: Level should be accurate | J41: Ready
...

Sheet Incident
A1: =COUNT(A5:A51) -> 36 | B1: Total # of Test cases
A3: Test Case ID | B3: Test Description/Title | C3: Module / Feature | D3: Functionality | E3: TestType | F3: Preconditions | G3: Test Steps | H3: Test Data/ User | I3: Expected Result | J3: Actual outcome | K3: Status | L3: Defect Retest reference
B4: Verify Vendor Admin can see Incident report Tab on external portal | C4: Incident Report | E4: Positive | G4: Login as a Vendor Admin user | I4: Vendor successfully logged in | K4: Pass
A5: 1 | C5: Incident Report | E5: Positive | G5: Navigate to “More” menu tab | I5: Report Incident” option is visible and clickable | K5: Pass
A6: 2 | B6: Verify - Report Incident should not be visible for Non Admin user | C6: Incident Report | E6: Positive | G6: Login as a Non Admin user Navigate to “More” menu tab | H6: ECMS Create & Update Enrollment ECMS External Manage Budgets ECMS Manage Budgets | I6: Report Incident” option should not be visible. | K6: Pass
A7: 3 | B7: Verify Vendor Admin should be able to submit an incident and Verify Subject, Category, Concern, Incident Date are marked required | C7: Incident Report | E7: Positive | G7: Login as a Vendor Admin user | I7: Vendor successfully logged in | K7: Pass
A8: 4 | C8: Incident Report | E8: Positive | G8: Navigate to “More” menu tab | I8: Report Incident” option is visible and clickable | K8: Pass
A9: 5 | C9: Incident Report | E9: Positive | G9: Click Submit | I9: Confirm system should respond with an error message " These required fields must be completed: Concern, Incident Date, Subject" | K9: Pass
A10: 6 | C10: Incident Report | E10: Positive | G10: Populate all the require fields and upload a PDF document | I10: Confirm document is uploaded successfully | K10: Pass
A11: 7 | B11: Verify Incident Intake Team member should be able to create an Incident in Salesforce. | C11: Incident Report | E11: Positive | G11: Navigate to Incident Case Tab Verify default status = New Navigate to Incident Case Tab CLICK + | I11: Confirm new page is displayed | K11: Pass
A12: 8 | C12: Incident Report | E12: Positive | G12: Click Save | I12: Confirm A new incident case is created successfully | K12: Pass
A13: 9 | B13: Verify System should notify Team member if escalation level 1 case is not updated within last 24 hrs. | C13: Incident Report | D13: Case Notification | E13: Positive | K13: In Design
A14: 10 | B14: Verify a new incident case should be created when send via email | E14: Positive | K14: In Design
A15: 11 | B15: Incident Management Team Member can select a status stage on Path | C15: Incident Report | D15: Update | E15: Positive | F15: User has Incident Management Team Member access. An Incident Case record exists and is accessible to the user. Path is configured on the Case object for the Status field | G15: Log in as an Incident Management Team Member. | H15: Incident Management Team Member | K15: In Design
A16: 12 | C16: Incident Report | D16: Update | E16: Positive | G16: Open any Incident Case record. | K16: In Design
A17: 13 | C17: Incident Report | D17: Update | E17: Positive | G17: On the Path component, click a different status stage than the current one. | I17: The selected stage becomes highlighted/selected on the Path (ready to be saved). No errors occur. | K17: In Design
A18: 14 | B18: Escalation Level field is visible and populated for Incident Management Team Member on Incident Case | C18: Incident Report | E18: Positive | F18: An Incident Case record exists with Escalation Level expected to be populated The Incident Case record is accessible to both: System Administrator Incident Management Team Member The test user for Incident Management Team Member is assigned the correct profile/permission sets. Test Data | G18: Log in as System Administrator. | H18: System Administrator. | K18: In Design
A19: 15 | C19: Incident Report | E19: Positive | G19: Navigate to Incident Cases and open the test Incident Case record. | K19: In Design
A20: 16 | C20: Incident Report | E20: Positive | G20: Verify the Escalation Level field is visible on the page and note the value displayed. | K20: In Design
A21: 17 | C21: Incident Report | E21: Positive | G21: Log out. | K21: In Design
A22: 18 | C22: Incident Report | E22: Positive | G22: Log in as Incident Management Team Member. | K22: In Design
A23: 19 | C23: Incident Report | E23: Positive | G23: Navigate to Incident Cases and open the same Incident Case record. | K23: In Design
A24: 20 | C24: Incident Report | E24: Positive | G24: Verify whether the Escalation Level field is visible on the page and whether it is populated. | I24: For Incident Management Team Member, the Escalation Level field is: Visible on the Incident Case record page (same relevant section as Admin), and Populated with the correct value (matches expected / matches Admin view). | K24: In Design
A25: 21 | C25: Incident Report | E25: Positive | K25: In Design
A26: 22 | B26: Verify Salesforce Case Record Validation | C26: Incident Report | E26: Positive | G26: Submit incident from portal. | K26: In Design
A27: 23 | C27: Incident Report | E27: Positive | G27: Login to Salesforce backend | K27: In Design
A28: 24 | C28: Incident Report | E28: Positive | G28: Search for newly created Case. | I28: Case record exists. Case fields populated correctly: Subject Category Concern Incident Date Case Origin = Experience Portal Contact & Account linked correctly. | K28: In Design
A29: 25 | B29: Verify Incident Ownership / PSG Assignment | C29: Incident Report | D29: Incident Ownership / PSG Assignment | E29: Positive | G29: Submit incident. Open case in Salesforce. | I29: Case assigned to correct: Queue OR Vendor Incident PSG Ownership matches design. No incorrect manual owner. | K29: In Design
A30: 26 | B30: Verify non Admin user should not be able to create an Incident | C30: Incident Report | D30: Negative Test – Non Vendor Admin User | E30: Positive | G30: Login as standard Experience user. Attempt direct URL access to Incident page. | I30: Access denied OR Redirected to homepage. No backend record created. | K30: In Design
A31: 27 | B31: Verify Create Incident via Email (Email-to-Case) Gets created successfully | C31: Incident Report | D31: Email-to-Case | E31: Positive | F31: Email-to-Case configured. ECMS intake address active. | G31: Send email to ECMS intake address. Include: Subject Description | I31: Case automatically created in Salesforce. Case Origin = Email Subject populated from email subject. Description populated from email body. Contact auto-associated (if match found). | K31: In Design
A32: 28 | B32: Verify ECMS Incident Intake Team should be able to create a case via salesforce, Create Incident via Salesforce UI | C32: Incident Report | D32: Create Incident via Salesforce UI | E32: Positive | G32: Login as Internal User. Navigate to Cases → New. | K32: In Design
A33: 29 | B33: Verify system should automatically assign case FCC for FCC Account | C33: Incident Report | D33: Auto-Routing to Intake Team | E33: Positive | G33: Select Record Type. Enter: Account Site Subject Category Click Save. | I33: Case successfully created. Record saved without errors. Routed automatically to Intake Team FCC | K33: In Design
A34: 30 | B34: Verify system should automatically assign case to Intake Team for CBO Account | C34: Incident Report | D34: Auto-Routing to Intake Team | E34: Positive | G34: Select Record Type. Enter: Account Site Subject Category Click Save. | I34: Case successfully created. Record saved without errors. Routed automatically to Intake Team TCO | K34: In Design
A35: 31 | B35: Verify Escalation Level Auto Calculation, Create case that qualifies for Escalation Level 1 | C35: Incident Report | D35: Escalation Level 1 Trigger | E35: Positive | I35: Escalation Level updated to Level 1. Notification triggered. Header view reflects escalation status. | K35: In Design
A36: 32 | B36: Verify when an Incident Management Team Update , confirm escalation level changes as per user action | C36: Incident Report | D36: Escalation Level change | E36: Positive | F36: Existing Escalation exist | G36: Building and Facility Safety and Security Facility and Maintenance Program is seeking to relocate to a new location CHANGE TO Building and Facility Safety and Security Facility and Maintenance Infant (under 12 months) room(s) does not have one crib or bassinet per child | I36: Confirm Escalation level change to 3 | K36: In Design
A37: 33 | B37: Vendor is not able to select site from checklist | G37: Login to Portal ->Click on Report Incident Fill the Required Fields → Select Account, Site | I37: Vendor Should be able to select site from the Checklist sites | J37: Vendor is not able to select site | K37: In Design | L37: https://prutech.atlassian.net/browse/DOEECMS-2066
A38: 34 | B38: Some fields are missing in Incident report case | G38: Login to Portal as CBO User Click on Report Incident → create new incidence report and save Issue 1 : Compare the Case in Portal and backend, In additional Information there are less feilds in backend compare to Portal some fields are missing Issue 2 : In backend We can see here Addtional Field is not there in Portal case form | I38: In both the Cases form should display the same feilds | J38: working as Fine | K38: In Design | L38: https://prutech.atlassian.net/browse/DOEECMS-2061
A39: 35 | B39: Account, site, subject are missing on Incident Cases | G39: Login to SF org as ECMS Intake Team Administrator Go to Incident Cases → Create New/Open which are already created. | I39: User should be able to see all the fields like Account, site, subject etc.. In Portal, User is able to see all the fields while creating but in salesforce org these fields were missing. | K39: In Design | L39: https://prutech.atlassian.net/browse/DOEECMS-2060
A40: 36 | B40: Account name is not a mandatory field but still getting error when trying to submit an Incident | G40: Log into Portal as FCCN User Click on Report Incident → Fill all the mandatory fields and Save. Note: Account and Site are not mandatory | I40: User should be able to submit Incident successfully but receiving error. | K40: In Design | L40: https://prutech.atlassian.net/browse/DOEECMS-2059
A52: 39
...

Sheet Checlklist-&Template
A1: =COUNT(A3:A70) -> 61 | B1: Total Test Cases
A2: Test Case ID | B2: Test Scenario | C2: Module / Feature | D2: Functionality | E2: TestType | F2: Preconditions | G2: Test Steps | H2: Test Data | I2: Expected Result | J2: Status | K2: Priority | L2: Defect Retest reference
A3: 1 | B3: Verify external userECMS_External_Checklist_Viewers PSG should only be allowed to populate checklist items and should not be allowed to change/update at the checklist template level | F3: External user exists with ECMS_External_Checklist_Viewers PSG; at least one checklist is assigned to the user. | G3: Login as external user → Navigate to Checklists | I3: Assigned checklist opens successfully | J3: Pass | L3: https://prutech.atlassian.net/browse/DOEECMS-1921
A4: 2 | G4: User click Edit and attempt to edit CHECKLIST Name, Owner, Envelope section, | I4: Confirm system should not allow user to edit | J4: Pass
A5: 3 | G5: Now user populate Checklist items | I5: Confirm system should allow user to populate | J5: Pass
A6: 4 | B6: Verify internal manager can create Checklisttemplates, author items, activate, assign, review, close/archive/reassign. | F6: Internal user exists with ECMS_Internal_Checklist_Manager PSG. | G6: Login as internal manager Launch ECMS App via app launcher AND Navigate to Checklist Templates Tab | I6: All admin actions available and executed successfully per role permissions. | J6: Pass
A7: 5 | G7: Click New button And enter Checklist Template Name and Click Save | I7: Confirm Checklist Template is created successfully | J7: Pass
A8: 6 | G8: Navigate to Checklist Template Items and click new | I8: Confirm New Checklist Template Item window should display Confirm Checkist template field is pre-populated Confirm Question section should have checklist template item label Required checkbox, Data Type, Due Date, section should have default due date and due date type field should exist. | J8: Pass
A9: 7 | G9: Populate the question section and add few questions required and add few questions optional Select Data type Text click Save Npte: Repeat this step multiple times depends Also add sequences | I9: Confirm all required and optional uestions are added successfully | J9: Pass
A10: 8 | G10: Navigate to Checklist Template that you just created and make it Active and click mark as current status | I10: Confirm checklist is now ACTIVE | J10: Pass
A11: 9 | G11: Click "Assign Checklist " | I11: Confirm Assign checklist page should display with the Checklist Name Envelope section having Respondent User field, Stage field, Notification frequency field and expiry date/time fields | J11: Pass
A12: 10 | G12: STEP10: select a respondent user who has ECMS_External_Checklist_Viewers PSG Populate notification frequency to Hour. select stage sent to respondent and populate expire date and click send checklists | J12: Pass
A13: 11 | G13: Now login as a the same external user ECMS_External_Checklist_Viewers PSG AND Navigate to Checklist tab | I13: Confirm the checklist that was just sent should exist | J13: Pass
A14: 12 | G14: Click on the Checklist and navigate to questionaire and click submit without populating the required fields | I14: Confirm system should display an error message | J14: Pass
A15: 13 | G15: Wait for an hour and then Navigate to Bell Icon | I15: Confirm Bell notification has notfication activated for the user | J15: Pass
A16: 14 | G16: User click Mark all as read | I16: Confirm all notification should now be removed | J16: Pass
A17: 15 | G17: Now populate all the required fields and optional fields and click Save | I17: confirm response is submitted successfully | J17: Pass
A18: 16 | G18: LogOut and login again | I18: Confirm user is successfully logged in again | J18: Pass
A19: 17 | G19: Navigate to the same checklist that was saved | I19: Confirm save questionaire should be saved and no changes occured | J19: Pass
A20: 18 | G20: Now CLICK sUBMIT | I20: Confirm system successfully processed the checklist | J20: Pass
A21: 19 | B21: Verify Checklist Manager should be able to view submitted Checklist by the External User | G21: Login as a Checklist Manager and navigate to ECMS via app launcher Then navigate to checklist | I21: Confirm user land on checklist | J21: Pass
A22: 20 | G22: Select submitted checklist by the external user in scenario 1 (Above) and Try to Edit User responses | I22: Confirm system should not allow user to edit submitted responses | J22: Fail
A23: 21 | B23: Verify non-manager internal user cannot create/activate templates or assign checklists. | F23: User without ECMS_Internal_Checklist_Manager PSG. | G23: Login as unauthorized user (Login as an Operations Director / operations Analyst. Navigate to Checklist Via app launcher | I23: Confirm Checklist should not exist | J23: Pass | L23: https://prutech.atlassian.net/browse/DOEECMS-1922
A24: 22 | B24: Verify system blocks template save when required fields are missing. | F24: Internal manager access. | G24: Login as a checklist manager AND Navigate to Checklist Via app launcher | I24: System display checklist Template page | J24: Pass
A25: 23 | G25: Leave Name/Respondent Type/Dates blank → Save. | I25: System shows validation messages; template not saved.
A26: 24 | B26: Verify Checklist Manager Should NOT be able to create a Checklist if expiration date is selected in the past | G26: Login as a Checklist Manager | I26: Logged in successfully | J26: Pass | L26: https://prutech.atlassian.net/browse/DOEECMS-1921
A27: 25 | G27: Launch ECMS via app launcher | J27: Pass
A28: 26 | G28: Navigate to Checklist Tab and click New | I28: Confirm Two radio button should display, From Template Create a New checklist without Template | J28: Pass | L28: https://prutech.atlassian.net/browse/DOEECMS-1922
A29: 27 | G29: Select Create a New checklist without Template radio button and click Next | I29: Confirm user view Information and envelope section | J29: Pass
A30: 28 | G30: DO not populate any fields and click save draft | I30: Confirm system respond with error messages for Checklist name field, respondent user field, expire date/time field | J30: Pass
A31: 29 | G31: Now populate checklist Name field and select respondent user, Select expire Date / Time in the past and click save | I31: Confirm system should respond with an error message not to allow user to create a checklist | J31: Fail
A32: 30 | B32: The system currently allows users to clone a checklist template that is expired and inactive. During the cloning process, the system copies the original Expiration Date and Time values into the new checklist record. As a result, the newly cloned checklist automatically becomes Inactive due to current logic | F32: Existing checklist template is expired and marked Inactive User has Checklist Manager permissions | G32: Login as Checklist Manager Navigate to the Checklist tab | I32: User lands on checklist | J32: Pass
A33: 31 | G33: Click New | I33: checklist page is displayed | J33: Pass
A34: 32 | G34: Select an existing checklist template that is expired and inactive | I34: user selection is selected | J34: Pass
A35: 33 | G35: Click the Clone button | I35: Checkistem Template is successfully cloned | J35: Pass
A36: 34 | G36: Observe the cloned checklist record | I36: The system should prevent cloned checklists from inheriting past expiration date/time values. When cloning: The Expiration Date and Time field should either be left blank, OR The system should prevent past dates from being saved, OR The system should not automatically mark cloned checklist records as inactive based on inherited past expiration values The cloned checklist should remain Active unless a valid future expiration date is explicitly set. | J36: Fail
A37: 35 | B37: Verify system enforces date logic: Expiration/Due date must be after Start date. | F37: Internal manager access. | G37: New Template → Set Start Date after Expiration date → Save. | I37: Validation error displayed; save blocked. | J37: Pass
A38: 36 | J38: Pass
A39: 37 | J39: Pass
A40: 38 | B40: Verify template items can be created with sequencing, label, type, and required flag. | F40: Template exists in Draft. | G40: Open Draft Template → Add Template Item → Enter Seq, Label, Type, Required → Save item. | I40: Item is saved and appears in template item list. | J40: Pass
...

Sheet QA Test Summary
A1: Green | B1: Internal reviewed
C2: Test Cases
B3: Module | C3: # Created | D3: # Design | E3: # Reviewed | F3: # Passed | G3: # Failed | H3: # Blocked | I3: # No Run | J3: Blocked% | K3: Failed% | L3: Passed% | M3: No Run %
B4: Budget | C4: =COUNT(Budget!$A$3:$A$1048576) -> 146 | D4: =COUNTIF(Budget!$J$3:$J$1048576,"In Design")+COUNTIF(Budget!$J$3:$J$1048576,"In design") -> 20 | E4: =COUNTIF(Budget!$J$3:$J$1048576,"Reviewed")+COUNTIF(Budget!$J$3:$J$1048576,"Reviewed Completed") -> 142 | F4: 100 | G4: =COUNTIF(Budget!$J$3:$J$1048576,"Fail")+COUNTIF(Budget!$J$3:$J$1048576,"Failed") -> 0 | H4: =COUNTIF(Budget!$J$3:$J$1048576,"Blocked") -> 0 | I4: =COUNTIF(Budget!$J$3:$J$1048576,"No Run")+COUNTIF(Budget!$J$3:$J$1048576,"No run") -> 0 | J4: =IF($C4=0,0,$H4/$C4) -> 0 | K4: =IF($C4=0,0,$G4/$C4) -> 0 | L4: =IF($C4=0,0,$F4/$C4) -> 0.68493151 | M4: =IF($C4=0,0,$I4/$C4) -> 0
B5: Seat & Capacity | C5: =COUNT('Seats & Capacity'!$A$3:$A$1048576) -> 31 | D5: =COUNTIF('Seats & Capacity'!$I$3:$I$1048576,"In Design")+COUNTIF('Seats & Capacity'!$I$3:$I$1048576,"In design") -> 0 | E5: =COUNTIF('Seats & Capacity'!$I$3:$I$1048576,"Reviewed")+COUNTIF('Seats & Capacity'!$I$3:$I$1048576,"Reviewed Completed") -> 0 | F5: =COUNTIF('Seats & Capacity'!$I$3:$I$1048576,"Pass")+COUNTIF('Seats & Capacity'!$I$3:$I$1048576,"Passed") -> 27 | G5: =COUNTIF('Seats & Capacity'!$I$3:$I$1048576,"Fail")+COUNTIF('Seats & Capacity'!$I$3:$I$1048576,"Failed") -> 4 | H5: =COUNTIF('Seats & Capacity'!$I$3:$I$1048576,"Blocked") -> 0 | I5: =COUNTIF('Seats & Capacity'!$I$3:$I$1048576,"No Run")+COUNTIF('Seats & Capacity'!$I$3:$I$1048576,"No run") -> 0 | J5: =IF($C5=0,0,$H5/$C5) -> 0 | K5: =IF($C5=0,0,$G5/$C5) -> 0.12903226 | L5: =IF($C5=0,0,$F5/$C5) -> 0.87096774 | M5: =IF($C5=0,0,$I5/$C5) -> 0
B6: Screening | C6: =COUNT(Screening!$A$4:$A$1048576) -> 29 | D6: =COUNTIF(Screening!$I$4:$I$1048576,"In Design")+COUNTIF(Screening!$I$4:$I$1048576,"In design") -> 0 | E6: =COUNTIF(Screening!$I$4:$I$1048576,"Reviewed")+COUNTIF(Screening!$I$4:$I$1048576,"Reviewed Completed") -> 0 | F6: =COUNTIF(Screening!$I$4:$I$1048576,"Pass")+COUNTIF(Screening!$I$4:$I$1048576,"Passed") -> 26 | G6: =COUNTIF(Screening!$I$4:$I$1048576,"Fail")+COUNTIF(Screening!$I$4:$I$1048576,"Failed") -> 1 | H6: =COUNTIF(Screening!$I$4:$I$1048576,"Blocked") -> 1 | I6: =COUNTIF(Screening!$I$4:$I$1048576,"No Run")+COUNTIF(Screening!$I$4:$I$1048576,"No run") -> 0 | J6: =IF($C6=0,0,$H6/$C6) -> 0.034482759 | K6: =IF($C6=0,0,$G6/$C6) -> 0.034482759 | L6: =IF($C6=0,0,$F6/$C6) -> 0.89655172 | M6: =IF($C6=0,0,$I6/$C6) -> 0
B7: Enrollment | C7: =COUNT(Enrollment!$A$3:$A$1048576) -> 47 | D7: =COUNTIF(Enrollment!$I$3:$I$1048576,"In Design")+COUNTIF(Enrollment!$I$3:$I$1048576,"In design") -> 0 | E7: =COUNTIF(Enrollment!$I$3:$I$1048576,"Reviewed")+COUNTIF(Enrollment!$I$3:$I$1048576,"Reviewed Completed") -> 0 | F7: =COUNTIF(Enrollment!$I$3:$I$1048576,"Pass")+COUNTIF(Enrollment!$I$3:$I$1048576,"Passed") -> 41 | G7: =COUNTIF(Enrollment!$I$3:$I$1048576,"Fail")+COUNTIF(Enrollment!$I$3:$I$1048576,"Failed") -> 6 | H7: =COUNTIF(Enrollment!$I$3:$I$1048576,"Blocked") -> 0 | I7: =COUNTIF(Enrollment!$I$3:$I$1048576,"No Run")+COUNTIF(Enrollment!$I$3:$I$1048576,"No run") -> 2 | J7: =IF($C7=0,0,$H7/$C7) -> 0 | K7: =IF($C7=0,0,$G7/$C7) -> 0.12765957 | L7: =IF($C7=0,0,$F7/$C7) -> 0.87234043 | M7: =IF($C7=0,0,$I7/$C7) -> 0.042553191
B8: Attendance | C8: =COUNT(Attendance!$A$3:$A$1048576) -> 95 | D8: =COUNTIF(Attendance!$K$3:$K$1048576,"In Design")+COUNTIF(Attendance!$K$3:$K$1048576,"In design") -> 38 | E8: =COUNTIF(Attendance!$K$3:$K$1048576,"Reviewed")+COUNTIF(Attendance!$K$3:$K$1048576,"Reviewed Completed") -> 0 | F8: 80 | G8: =COUNTIF(Attendance!$K$3:$K$1048576,"Fail")+COUNTIF(Attendance!$K$3:$K$1048576,"Failed") -> 4 | H8: =COUNTIF(Attendance!$K$3:$K$1048576,"Blocked") -> 0 | I8: =COUNTIF(Attendance!$K$3:$K$1048576,"No Run")+COUNTIF(Attendance!$K$3:$K$1048576,"No run") -> 0 | J8: =IF($C8=0,0,$H8/$C8) -> 0 | K8: =IF($C8=0,0,$G8/$C8) -> 0.042105263 | L8: =IF($C8=0,0,$F8/$C8) -> 0.84210526 | M8: =IF($C8=0,0,$I8/$C8) -> 0
B9: Incident | C9: 56 | D9: =COUNTIF(Incident!$K$4:$K$1048576,"In Design")+COUNTIF(Incident!$K$4:$K$1048576,"In design") -> 56 | E9: =COUNTIF(Incident!$K$4:$K$1048576,"Reviewed")+COUNTIF(Incident!$K$4:$K$1048576,"Reviewed Completed") -> 0 | F9: 50 | G9: 5 | H9: =COUNTIF(Incident!$K$4:$K$1048576,"Blocked") -> 0 | I9: =COUNTIF(Incident!$K$4:$K$1048576,"No Run")+COUNTIF(Incident!$K$4:$K$1048576,"No run") -> 0 | J9: =IF($C9=0,0,$H9/$C9) -> 0 | K9: =IF($C9=0,0,$G9/$C9) -> 0.089285714 | L9: =IF($C9=0,0,$F9/$C9) -> 0.89285714 | M9: =IF($C9=0,0,$I9/$C9) -> 0
B10: Monitoring/Coaching log | C10: =COUNT('Coaching log'!$A$4:$A$1048576) -> 59 | D10: =COUNTIF('Coaching log'!$I$4:$I$1048576,"In Design")+COUNTIF('Coaching log'!$I$4:$I$1048576,"In design") -> 0 | E10: =COUNTIF('Coaching log'!$I$4:$I$1048576,"Reviewed")+COUNTIF('Coaching log'!$I$4:$I$1048576,"Reviewed Completed") -> 0 | F10: 45 | G10: =COUNTIF('Coaching log'!$I$4:$I$1048576,"Fail")+COUNTIF('Coaching log'!$I$4:$I$1048576,"Failed") -> 2 | H10: =COUNTIF('Coaching log'!$I$4:$I$1048576,"Blocked") -> 0 | I10: =COUNTIF('Coaching log'!$I$4:$I$1048576,"No Run")+COUNTIF('Coaching log'!$I$4:$I$1048576,"No run") -> 0 | J10: =IF($C10=0,0,$H10/$C10) -> 0 | K10: =IF($C10=0,0,$G10/$C10) -> 0.033898305 | L10: =IF($C10=0,0,$F10/$C10) -> 0.76271186 | M10: =IF($C10=0,0,$I10/$C10) -> 0
B11: Reporting / Dashboard | C11: 0 | D11: 0 | E11: 0 | F11: 0 | G11: 0 | H11: 0 | I11: 0 | J11: 0 | K11: 0 | L11: 0 | M11: 0
B12: Invoice | C12: =COUNT(Invoice!$A$3:$A$1048576) -> 38 | D12: =COUNTIF(Invoice!$J$3:$J$1048576,"In Design")+COUNTIF(Invoice!$J$3:$J$1048576,"In design") -> 0 | E12: =COUNTIF(Invoice!$J$3:$J$1048576,"Reviewed")+COUNTIF(Invoice!$J$3:$J$1048576,"Reviewed Completed") -> 0 | F12: =COUNTIF(Invoice!$J$3:$J$1048576,"Pass")+COUNTIF(Invoice!$J$3:$J$1048576,"Passed") -> 12 | G12: =COUNTIF(Invoice!$J$3:$J$1048576,"Fail")+COUNTIF(Invoice!$J$3:$J$1048576,"Failed") -> 0 | H12: =COUNTIF(Invoice!$J$3:$J$1048576,"Blocked") -> 26 | I12: =COUNTIF(Invoice!$J$3:$J$1048576,"No Run")+COUNTIF(Invoice!$J$3:$J$1048576,"No run") -> 0 | J12: =IF($C12=0,0,$H12/$C12) -> 0.68421053 | K12: =IF($C12=0,0,$G12/$C12) -> 0 | L12: =IF($C12=0,0,$F12/$C12) -> 0.31578947 | M12: =IF($C12=0,0,$I12/$C12) -> 0
B13: Checklist & Checklist Template | C13: ='Checlklist-&Template'!A1 -> 61 | D13: 3 | E13: =COUNTIF(Invoice!$J$3:$J$1048576,"Reviewed")+COUNTIF(Invoice!$J$3:$J$1048576,"Reviewed Completed") -> 0 | F13: 55 | G13: 3 | H13: =COUNTIF(Invoice!$J$3:$J$1048576,"Blocked") -> 26 | I13: =COUNTIF(Invoice!$J$3:$J$1048576,"No Run")+COUNTIF(Invoice!$J$3:$J$1048576,"No run") -> 0 | J13: =IF($C13=0,0,$H13/$C13) -> 0.42622951 | K13: =IF($C13=0,0,$G13/$C13) -> 0.049180328 | L13: =IF($C13=0,0,$F13/$C13) -> 0.90163934 | M13: =IF($C13=0,0,$I13/$C13) -> 0
B14: Procurement | C14: 0 | D14: 0 | E14: 0 | F14: 0 | G14: 0 | H14: 0 | I14: 0 | J14: 0 | K14: 0 | L14: 0 | M14: 0
B15: Document Management | C15: 0 | D15: 0 | E15: 0 | F15: 0 | G15: 0 | H15: 0 | I15: 0 | J15: 0 | K15: 0 | L15: 0 | M15: 0
B16: Data Migration | C16: 0 | D16: 0 | E16: 0 | F16: 0 | G16: 0 | H16: 0 | I16: 0 | J16: 0 | K16: 0 | L16: 0 | M16: 0
B17: ESMS Integration with External Systems | C17: 0 | D17: 0 | E17: 0 | F17: 0 | G17: 0 | H17: 0 | I17: 0 | J17: 0 | K17: 0 | L17: 0 | M17: 0
C18: 0 | D18: 0 | E18: 0 | F18: 0 | G18: 0 | H18: 0 | I18: =C18-(F18-G18) -> 0 | J18: =(H18/C18) -> #DIV/0! | K18: =IF($C18=0,0,$G18/$C18) -> 0 | L18: =IF($C18=0,0,$F18/$C18) -> 0 | M18: =I18/(F18+G18) -> #DIV/0!
C19: 0 | D19: 0 | E19: 0 | F19: 0 | G19: 0 | H19: 0 | I19: =C19-(F19-G19) -> 0 | J19: =(H19/C19) -> #DIV/0! | K19: =IF($C19=0,0,$G19/$C19) -> 0 | L19: =IF($C19=0,0,$F19/$C19) -> 0 | M19: =I19/(F19+G19) -> #DIV/0!
B20: Net Total | C20: =SUM(C4:C18) -> 562 | D20: =SUM(D4:D18) -> 117 | E20: =SUM(E4:E18) -> 142 | F20: =SUM(F4:F18) -> 436 | G20: =SUM(G4:G18) -> 25 | H20: =SUM(H4:H18) -> 53 | I20: =C20-(F20-G20) -> 151 | J20: =IF($C20=0,0,$H20/$C20) -> 0.09430605 | K20: =IF($C20=0,0,$G20/$C20) -> 0.044483986 | L20: =IF($C20=0,0,$F20/$C20) -> 0.77580071 | M20: =IF($C20=0,0,$I20/$C20) -> 0.26868327

Sheet Seats & Capacity
A1: =COUNT(A3:A44) -> 31
A2: Test Case ID | B2: Test Description/Title | C2: Module / Feature | D2: Preconditions | E2: Test Steps | F2: Test Data/ User | G2: Expected Result | H2: Actual outcome | I2: Status | J2: Defect Retest reference
A3: 1 | B3: verify that vendor is able lo login SF | C3: Seats& Capacity | E3: Login -->SF | F3: System admin | G3: Login sucessfully | H3: Working as Expected | I3: Pass
A4: 2 | B4: Verify that vendo user have setup has done perfect | C4: Seats& Capacity | D4: Check whether your user has PSG- Internal Admin | E4: ECMS -->Homepage | F4: Bunny/ 3-K class p | G4: Able to view home page | H4: Working as Expected | I4: Pass
A5: 3 | E5: Homepage-->setup | F5: Bunny/ 3-K class p | G5: All the required presetup has done for the user | H5: Working as Expected | I5: Pass
A6: 4 | E6: setup-->user | F6: Bunny/ 3-K class p | H6: Working as Expected | I6: Pass
A7: 5 | E7: User-->PSG Assign | F7: Bunny/ 3-K class p | H7: Working as Expected | I7: Pass
A8: 6 | E8: Back to Homepage | F8: Bunny/ 3-K class p | G8: Vendor is able to view seats and capacity by site class | H8: Working as Expected | I8: Pass
A9: 7 | B9: Verify that vendor is able View Seat Capacities by Site​ | C9: Seats& Capacity | E9: Homepage-->Account--> desired account link | F9: Bunny/ 3-K class p | H9: Working as Expected | I9: Pass
A10: 8 | E10: Account-->Quick link | F10: Bunny/ 3-K class p | H10: Working as Expected | I10: Pass
A11: 9 | E11: Account-->Quick link--> desired site | F11: Bunny/ 3-K class p | H11: Working as Expected | I11: Pass
A12: 10 | E12: Site-->Quicl links | F12: Bunny/ 3-K class p | H12: Working as Expected | I12: Pass
A13: 11 | E13: site-->Class desired link | F13: Bunny/ 3-K class p | H13: Working as Expected | I13: Pass
A14: 12 | B14: "the vendor is able to observe that seats are getting auto filled" | C14: Seats& Capacity | E14: Portal-->create Enrollment | F14: Bunny/ 3-K class p | G14: The seats auto updated when submitting enrollment | H14: working as Expected | I14: Pass
A15: 13 | E15: Portal--> submit enrolment | F15: Bunny/ 3-K class p | I15: Pass
A16: 14 | E16: Back to SF--> desired classes | F16: Bunny/ 3-K class p | I16: Pass
A17: 15 | E17: class-->select class | F17: Bunny/ 3-K class p | I17: Pass
A18: 16 | E18: class-->view | F18: Bunny/ 3-K class p | I18: Pass
A19: 17 | E19: site-->view the capacity | F19: Bunny/ 3-K class p | G19: Able to view the seat and capacity occupied | H19: Working as Expected | I19: Pass | J19: https://prutech.atlassian.net/browse/DOEECMS-1892 https://prutech.atlassian.net/browse/DOEECMS-1968
A20: 18 | B20: View a Full Seat Capacity Class ​ | C20: Seats& Capacity | E20: Site-->view the capacity --> Full | F20: Bunny/ 3-K class p | H20: Working as Expected | I20: Pass
A21: 19 | B21: Verify that Vendor is able to edit capacity for active enrolled classes | C21: Seats& Capacity | E21: Site-->view the capacity --> Full-->Edit | F21: Bunny/ 3-K class p | G21: Verify that Vendor is able to edit capacity for active enrolled classes | H21: the vendor is not able to edit the capacity as tere are active enrollments in the class and populated an error | I21: Fail | J21: https://prutech.atlassian.net/browse/DOEECMS-1586 https://prutech.atlassian.net/browse/DOEECMS-1893
A22: 20 | B22: Verify that vendor is able to submit enrolment for capacity is full related site | C22: Seats& Capacity | D22: the class capacity must be full | E22: Login-->portal | F22: Bunny/ 3-K class p | G22: While create an sumit enrollment, the enrolmemt is not able to submit and the error has to populate | H22: Working as Expected | I22: Pass
A23: 21 | C23: Seats& Capacity | E23: Create enrolment--> submit | F23: Bunny/ 3-K class p | H23: Working as Expected | I23: Pass
A24: 22 | B24: Verify that vendor is able to see the other related sites classes capacity in the portal | C24: Seats& Capacity | D24: Validation- The vendor is only able to see their own sites related capacity in the portal | E24: Provision contact-->functions | F24: Bunny/ 3-K class p | G24: The vendor is not able to see the other site related classes or Capacity in the Portal | H24: woorking As expected | I24: Pass
A25: 23 | E25: Provision contact-->Site | F25: Bunny/ 3-K class p | I25: Pass
A26: 24 | E26: Login--> Portal | F26: Bunny/ 3-K class p | I26: Pass
A27: 25 | E27: Portal-->Site | F27: Bunny/ 3-K class p | I27: Pass
A28: 26 | E28: Portal-->classes | F28: Bunny/ 3-K class p | I28: Pass
A29: 27 | E29: Portal-->classes-->View Capacity | F29: Bunny/ 3-K class p | I29: Pass
A30: 28 | B30: Related List Quick Links" not loading for Internal Admin user | E30: Login-->Internal admin Navigate-->site Site-->Quicl Links | F30: Bunny/ 3-K class p | G30: The Related List Quick Links should load and display all applicable quick links for the record. | H30: The section does not load; quick links are missing or the component remains blank and shows in processing. | I30: Fail | J30: https://prutech.atlassian.net/browse/DOEECMS-1886
A31: 29 | B31: Internal Administrators do not have access to the Dashboards app | E31: Log in as an ECMS Internal Administrator. Navigate to the App Launcher. Search for “Dashboards”. Observe that the Dashboards app is missing / not visible. | G31: Internal Administrators should see and access the Dashboards app in the App Launcher. They should be able to open the Seat Capacity Planning Dashboard and related reports. Dashboard access should be included as part of the ECMS Admin Internal permission set. | H31: working As expected | I31: Pass | J31: https://prutech.atlassian.net/browse/DOEECMS-1891
A32: 30 | B32: A defect has been identified in the ECMS Seat Capacity module where a Class record is being created or saved without a valid Seat Capacity value (0 or null), while the Seats Occupied field displays a positive number. | E32: Navigate to Sites Master → Classes. Create or open an existing Class record. Leave Seat Capacity = 0 or blank. Ensure the system displays Seats Occupied > 0 (already existing enrollments or data mismatch). Save the record. Observe that the system allows saving the Class, despite invalid/contradictory values. | G32: Seat Capacity must be a required numeric field. The system must not allow creation or update of a Class record unless a valid Seat Capacity value is provided. Seat Capacity should never be allowed to remain 0, blank, or null if Seats Occupied is greater than 0. A validation error message should prevent saving until corrected. | H32: The system allows Class creation or update with Seat Capacity = 0 / null. | I32: Fail | J32: https://prutech.atlassian.net/browse/DOEECMS-1890
A33: 31 | B33: Seat Capacity Planning Dashboard - Capacity Vs Occupancy by Seat Type Column chart/ Report is not Visible | E33: Navigate to the ECMS home screen. Click on the nine dots on the top navigation bar and type “Dashboards.” Click on “Dashboards.” Click “All Dashboards” in the left most navigation pane. Click on the “Seat Capacity Planning Dashboard” link in the leftmost column. Capacity Vs Occupancy by Seat Type Column chart/ Report is not Visible | G33: Capacity Vs Occupancy by Seat Type Column chart with Report should be displayed correctly | H33: Capacity Vs Occupancy by Seat Type Column chart/ Report is not Visible | I33: Fail | J33: https://prutech.atlassian.net/browse/DOEECMS-2030

Sheet Enrollment
A1: =COUNT(A3:A63) -> 47 | B1: Total test cases
A2: Test Case ID | B2: Test Description/Title | C2: Module / Feature | D2: Preconditions | E2: Test Steps | F2: Test Data/ User | G2: Expected Result | H2: Actual outcome | I2: Status | J2: Defect Retest reference
A3: 1 | B3: Verify that admin user logged into ECMS-SF | C3: Enrollment | E3: Login SF-->Correct Credentials | F3: Admin user | G3: Loggedin in SF | H3: Working as Expected | I3: Pass
